Workbook
Name 個股清單: OFFSET('公司檔案'!$A$2,0,0,COUNTA('公司檔案'!$A:$A)-1,1)

Sheet 儀表板
B2: 標的觀察儀表板
B3: 在下方「選擇個股」的下拉選單挑一檔，公司小檔案、價位和評分會自動帶出來
B5: 追蹤標的（檔） | D5: 今日即時（列） | G5: 平均分 ≥ 9（檔） | I5: TP1 漲幅中位數
B6: =SUMPRODUCT(('標的清單'!$C$3:$C$1000<>"")/COUNTIF('標的清單'!$C$3:$C$1000,'標的清單'!$C$3:$C$1000&"")) -> 44 | D6: =COUNTIF('標的清單'!$A$3:$A$1000,"今日即時") -> 10 | G6: =COUNTIF('標的清單'!$O$3:$O$1000,">=9") -> 3 | I6: =MEDIAN('標的清單'!$K$3:$K$1000) -> 0.29583333
B8: 選擇個股 ▸ | C8: 3037 | E8: =IF($L$8=0,"",IF(COUNTIF('標的清單'!$C$3:$C$1000,$C$8)>1,"⚠ 這檔有 "&COUNTIF('標的清單'!$C$3:$C$1000,$C$8)&" 組價位，下面顯示第 1 組","")) | L8: =IFERROR(MATCH($C$8,'標的清單'!$C$1:$C$1000,0),0) -> 4 | M8: =IFERROR(MATCH($C$8,'公司檔案'!$A$1:$A$1000,0),0) -> 3
B10: 公司小檔案 | G10: 我的買點與目標價
B11: =IF($M$8=0,"（公司檔案裡沒有這檔）",IF($M$8=0,"",IF(INDEX('公司檔案'!$B$1:$B$1000,$M$8)="","",INDEX('公司檔案'!$B$1:$B$1000,$M$8)))) -> 欣興 | G11: 項目 | H11: 價位 | I11: 距買點1
B12: =IF($M$8=0,"",$C$8&" · "&IF($M$8=0,"",IF(INDEX('公司檔案'!$C$1:$C$1000,$M$8)="","",INDEX('公司檔案'!$C$1:$C$1000,$M$8)))&" · "&IF($M$8=0,"",IF(INDEX('公司檔案'!$D$1:$D$1000,$M$8)="","",INDEX('公司檔案'!$D$1:$D$1000,$M$8)))&IF(IF($L$8=0,"",IF(INDEX('標的清單'!$A$1:$A$1000,$L$8)="","",INDEX('標的清單'!$A$1:$A$1000,$L$8)))="",""," · "&IF($L$8=0,"",IF(INDEX('標的清單'!$A$1:$A$1000,$L$8)="","",INDEX('標的清單'!$A$1:$A$1000,$L$8))))) -> 3037 · 台股 · PCB／IC 載板 · 今日即時 | G12: TP3 | H12: =IF($L$8=0,"",IF(INDEX('標的清單'!$J$1:$J$1000,$L$8)="","",INDEX('標的清單'!$J$1:$J$1000,$L$8))) | I12: =IF(OR(H12="",$H$15=""),"",H12/$H$15-1) | J12: =IF(I12="","",REPT("▮",MIN(18,ROUND(ABS(I12)*30,0))))
B13: =IF($M$8=0,"",IF(INDEX('公司檔案'!$F$1:$F$1000,$M$8)="","",INDEX('公司檔案'!$F$1:$F$1000,$M$8))) -> ABF 載板與高階 PCB 龍頭 | G13: TP2 | H13: =IF($L$8=0,"",IF(INDEX('標的清單'!$I$1:$I$1000,$L$8)="","",INDEX('標的清單'!$I$1:$I$1000,$L$8))) -> 1690 | I13: =IF(OR(H13="",$H$15=""),"",H13/$H$15-1) -> 0.52252252 | J13: =IF(I13="","",REPT("▮",MIN(18,ROUND(ABS(I13)*30,0)))) -> ▮▮▮▮▮▮▮▮▮▮▮▮▮▮▮▮
B14: 股本 | C14: =IF(IF($M$8=0,"",IF(INDEX('公司檔案'!$E$1:$E$1000,$M$8)="","",INDEX('公司檔案'!$E$1:$E$1000,$M$8)))="",IF($M$8=0,"","待補"),TEXT(IF($M$8=0,"",IF(INDEX('公司檔案'!$E$1:$E$1000,$M$8)="","",INDEX('公司檔案'!$E$1:$E$1000,$M$8))),"#,##0.00")&" 億元（約 "&TEXT(IF($M$8=0,"",IF(INDEX('公司檔案'!$E$1:$E$1000,$M$8)="","",INDEX('公司檔案'!$E$1:$E$1000,$M$8)))*1000,"#,##0")&" 萬股）") -> 164.13 億元（約 164,130 萬股） | G14: TP1 | H14: =IF($L$8=0,"",IF(INDEX('標的清單'!$H$1:$H$1000,$L$8)="","",INDEX('標的清單'!$H$1:$H$1000,$L$8))) -> 1450 | I14: =IF(OR(H14="",$H$15=""),"",H14/$H$15-1) -> 0.30630631 | J14: =IF(I14="","",REPT("▮",MIN(18,ROUND(ABS(I14)*30,0)))) -> ▮▮▮▮▮▮▮▮▮
B15: 主要業務 | C15: =IF($M$8=0,"",IF(INDEX('公司檔案'!$G$1:$G$1000,$M$8)="","",INDEX('公司檔案'!$G$1:$G$1000,$M$8))) -> 全球主要的 IC 載板（ABF、BT）與 HDI、軟硬板廠，客戶涵蓋 CPU、GPU 與網通晶片大廠。 | G15: 買點1 | H15: =IF($L$8=0,"",IF(INDEX('標的清單'!$E$1:$E$1000,$L$8)="","",INDEX('標的清單'!$E$1:$E$1000,$L$8))) -> 1110 | J15: =IF(H15="","","◆ 基準") -> ◆ 基準
G16: 買點2 | H16: =IF($L$8=0,"",IF(INDEX('標的清單'!$F$1:$F$1000,$L$8)="","",INDEX('標的清單'!$F$1:$F$1000,$L$8))) | I16: =IF(OR(H16="",$H$15=""),"",H16/$H$15-1) | J16: =IF(I16="","",REPT("▮",MIN(18,ROUND(ABS(I16)*30,0))))
G17: 超級好買點 | H17: =IF($L$8=0,"",IF(INDEX('標的清單'!$G$1:$G$1000,$L$8)="","",INDEX('標的清單'!$G$1:$G$1000,$L$8))) -> 1025 | I17: =IF(OR(H17="",$H$15=""),"",H17/$H$15-1) -> -0.076576577 | J17: =IF(I17="","",REPT("▮",MIN(18,ROUND(ABS(I17)*30,0)))) -> ▮▮
B19: AI 題材 | C19: =IF($M$8=0,"",IF(INDEX('公司檔案'!$H$1:$H$1000,$M$8)="","",INDEX('公司檔案'!$H$1:$H$1000,$M$8))) -> ABF 載板、AI GPU、ASIC | G19: 評分
B20: 題材說明 | C20: =IF($M$8=0,"",IF(INDEX('公司檔案'!$I$1:$I$1000,$M$8)="","",INDEX('公司檔案'!$I$1:$I$1000,$M$8))) -> AI 加速器晶片面積大、層數高，帶動高階 ABF 載板用量與單價，是 AI 伺服器上游的關鍵材料供應鏈。 | G20: 技術面 | H20: =IF($L$8=0,"",IF(INDEX('標的清單'!$L$1:$L$1000,$L$8)="","",INDEX('標的清單'!$L$1:$L$1000,$L$8))) -> 9 | I20: =IF(H20="","",REPT("■",ROUND(H20,0))&REPT("□",10-ROUND(H20,0))) -> ■■■■■■■■■□
G21: 把握度 | H21: =IF($L$8=0,"",IF(INDEX('標的清單'!$M$1:$M$1000,$L$8)="","",INDEX('標的清單'!$M$1:$M$1000,$L$8))) -> 9 | I21: =IF(H21="","",REPT("■",ROUND(H21,0))&REPT("□",10-ROUND(H21,0))) -> ■■■■■■■■■□
G22: 基本面 | H22: =IF($L$8=0,"",IF(INDEX('標的清單'!$N$1:$N$1000,$L$8)="","",INDEX('標的清單'!$N$1:$N$1000,$L$8))) -> 10 | I22: =IF(H22="","",REPT("■",ROUND(H22,0))&REPT("□",10-ROUND(H22,0))) -> ■■■■■■■■■■
G23: 平均分 | H23: =IF($L$8=0,"",IF(INDEX('標的清單'!$O$1:$O$1000,$L$8)="","",INDEX('標的清單'!$O$1:$O$1000,$L$8))) -> 9.3333333 | I23: =IF(H23="","",REPT("■",ROUND(H23,0))&REPT("□",10-ROUND(H23,0))) -> ■■■■■■■■■□
B24: 連結 | C24: =IF($M$8=0,"",IF(IF($M$8=0,"",IF(INDEX('公司檔案'!$C$1:$C$1000,$M$8)="","",INDEX('公司檔案'!$C$1:$C$1000,$M$8)))="台股",HYPERLINK("https://tw.stock.yahoo.com/quote/"&$C$8&"/profile","Yahoo 公司資料 ↗"),HYPERLINK("https://finance.yahoo.com/quote/"&$C$8&IF(IF($M$8=0,"",IF(INDEX('公司檔案'!$C$1:$C$1000,$M$8)="","",INDEX('公司檔案'!$C$1:$C$1000,$M$8)))="日股",".T","")&"/profile","Yahoo Finance ↗"))) -> Yahoo 公司資料 ↗ | G24: 備註 | H24: =IF($L$8=0,"",IF(INDEX('標的清單'!$P$1:$P$1000,$L$8)="","",INDEX('標的清單'!$P$1:$P$1000,$L$8)))
B27: 公司檔案的股本與主要業務來自 Yahoo 奇摩股市公司資料（2026/10/07 查詢）；AI 題材為公開資訊整理，僅供研究參考。

Sheet 標的清單
A1: 基本資料 | E1: 買點 | H1: 目標價 | L1: 評分 (0–10) | P1: 備註
A2: 分類 | B2: 市場 | C2: 代號 | D2: 名稱 | E2: 買點1 | F2: 買點2 | G2: 超級好買點 | H2: TP1 | I2: TP2 | J2: TP3 | K2: TP1 漲幅 | L2: 技術面 | M2: 把握度 | N2: 基本面 | O2: 平均分 | P2: 備註
A3: 今日即時 | B3: 台股 | C3: 6147 | D3: =IFERROR(INDEX('公司檔案'!$B:$B,MATCH(C3,'公司檔案'!$A:$A,0)),"請先到公司檔案新增") -> 頎邦 | E3: 210 | G3: 200 | H3: 274 | I3: 310 | J3: 380 | K3: =IF(AND(ISNUMBER(E3),ISNUMBER(H3)),H3/E3-1,"") -> 0.3047619 | L3: 8.8 | M3: 9 | N3: 10 | O3: =IF(COUNT(L3:N3)=3,AVERAGE(L3:N3),"") -> 9.2666667
A4: 今日即時 | B4: 台股 | C4: 3037 | D4: =IFERROR(INDEX('公司檔案'!$B:$B,MATCH(C4,'公司檔案'!$A:$A,0)),"請先到公司檔案新增") -> 欣興 | E4: 1110 | G4: 1025 | H4: 1450 | I4: 1690 | K4: =IF(AND(ISNUMBER(E4),ISNUMBER(H4)),H4/E4-1,"") -> 0.30630631 | L4: 9 | M4: 9 | N4: 10 | O4: =IF(COUNT(L4:N4)=3,AVERAGE(L4:N4),"") -> 9.3333333
A5: 今日即時 | B5: 台股 | C5: 2344 | D5: =IFERROR(INDEX('公司檔案'!$B:$B,MATCH(C5,'公司檔案'!$A:$A,0)),"請先到公司檔案新增") -> 華邦電 | E5: 175 | F5: 158 | G5: 140 | H5: 230 | I5: 278 | J5: 300 | K5: =IF(AND(ISNUMBER(E5),ISNUMBER(H5)),H5/E5-1,"") -> 0.31428571 | L5: 9 | O5: =IF(COUNT(L5:N5)=3,AVERAGE(L5:N5),"")
A6: 今日即時 | B6: 台股 | C6: 6531 | D6: =IFERROR(INDEX('公司檔案'!$B:$B,MATCH(C6,'公司檔案'!$A:$A,0)),"請先到公司檔案新增") -> 愛普 | E6: 940 | G6: 880 | H6: 1300 | I6: 1650 | J6: 1950 | K6: =IF(AND(ISNUMBER(E6),ISNUMBER(H6)),H6/E6-1,"") -> 0.38297872 | L6: 9.1 | M6: 7 | N6: 10 | O6: =IF(COUNT(L6:N6)=3,AVERAGE(L6:N6),"") -> 8.7
A7: 今日即時 | B7: 台股 | C7: 3653 | D7: =IFERROR(INDEX('公司檔案'!$B:$B,MATCH(C7,'公司檔案'!$A:$A,0)),"請先到公司檔案新增") -> 健策 | E7: 6700 | F7: 6500 | G7: 6100 | H7: 8300 | I7: 10000 | K7: =IF(AND(ISNUMBER(E7),ISNUMBER(H7)),H7/E7-1,"") -> 0.23880597 | L7: 8.9 | O7: =IF(COUNT(L7:N7)=3,AVERAGE(L7:N7),"")
A8: 今日即時 | B8: 台股 | C8: 3665 | D8: =IFERROR(INDEX('公司檔案'!$B:$B,MATCH(C8,'公司檔案'!$A:$A,0)),"請先到公司檔案新增") -> 貿聯-KY | E8: 2250 | G8: 2150 | H8: 2900 | I8: 3600 | K8: =IF(AND(ISNUMBER(E8),ISNUMBER(H8)),H8/E8-1,"") -> 0.28888889 | L8: 8.9 | M8: 7.5 | N8: 9.5 | O8: =IF(COUNT(L8:N8)=3,AVERAGE(L8:N8),"") -> 8.6333333
A9: 今日即時 | B9: 台股 | C9: 3595 | D9: =IFERROR(INDEX('公司檔案'!$B:$B,MATCH(C9,'公司檔案'!$A:$A,0)),"請先到公司檔案新增") -> 山太士 | E9: 1470 | G9: 1250 | H9: 2200 | I9: 3000 | J9: 3700 | K9: =IF(AND(ISNUMBER(E9),ISNUMBER(H9)),H9/E9-1,"") -> 0.49659864 | L9: 8.7 | O9: =IF(COUNT(L9:N9)=3,AVERAGE(L9:N9),"")
A10: 今日即時 | B10: 台股 | C10: 3081 | D10: =IFERROR(INDEX('公司檔案'!$B:$B,MATCH(C10,'公司檔案'!$A:$A,0)),"請先到公司檔案新增") -> 聯亞 | E10: 3000 | F10: 2900 | G10: 2700 | H10: 3550 | I10: 4300 | J10: 5100 | K10: =IF(AND(ISNUMBER(E10),ISNUMBER(H10)),H10/E10-1,"") -> 0.18333333 | L10: 9 | O10: =IF(COUNT(L10:N10)=3,AVERAGE(L10:N10),"")
A11: 今日即時 | B11: 台股 | C11: 2327 | D11: =IFERROR(INDEX('公司檔案'!$B:$B,MATCH(C11,'公司檔案'!$A:$A,0)),"請先到公司檔案新增") -> 國巨 | E11: 600 | F11: 580 | G11: 530 | H11: 730 | I11: 860 | K11: =IF(AND(ISNUMBER(E11),ISNUMBER(H11)),H11/E11-1,"") -> 0.21666667 | L11: 8.9 | O11: =IF(COUNT(L11:N11)=3,AVERAGE(L11:N11),"")
A12: 今日即時 | B12: 台股 | C12: 3533 | D12: =IFERROR(INDEX('公司檔案'!$B:$B,MATCH(C12,'公司檔案'!$A:$A,0)),"請先到公司檔案新增") -> 嘉澤 | E12: 1850 | F12: 1770 | G12: 1600 | H12: 2600 | I12: 3200 | J12: 4300 | K12: =IF(AND(ISNUMBER(E12),ISNUMBER(H12)),H12/E12-1,"") -> 0.40540541 | L12: 8.6 | O12: =IF(COUNT(L12:N12)=3,AVERAGE(L12:N12),"")
A13: 追蹤中 | B13: 台股 | C13: 6907 | D13: =IFERROR(INDEX('公司檔案'!$B:$B,MATCH(C13,'公司檔案'!$A:$A,0)),"請先到公司檔案新增") -> 雅特力-KY | E13: 180 | G13: 168 | H13: 280 | I13: 400 | K13: =IF(AND(ISNUMBER(E13),ISNUMBER(H13)),H13/E13-1,"") -> 0.55555556 | L13: 8.8 | M13: 10 | N13: 8.5 | O13: =IF(COUNT(L13:N13)=3,AVERAGE(L13:N13),"") -> 9.1
A14: 追蹤中 | B14: 台股 | C14: 7769 | D14: =IFERROR(INDEX('公司檔案'!$B:$B,MATCH(C14,'公司檔案'!$A:$A,0)),"請先到公司檔案新增") -> 鴻勁 | E14: 6300 | F14: 6000 | G14: 5700 | H14: 8000 | I14: 9150 | J14: 10050 | K14: =IF(AND(ISNUMBER(E14),ISNUMBER(H14)),H14/E14-1,"") -> 0.26984127 | L14: 8.8 | O14: =IF(COUNT(L14:N14)=3,AVERAGE(L14:N14),"")
A15: 追蹤中 | B15: 台股 | C15: 6190 | D15: =IFERROR(INDEX('公司檔案'!$B:$B,MATCH(C15,'公司檔案'!$A:$A,0)),"請先到公司檔案新增") -> 萬泰科 | E15: 70 | F15: 67 | G15: 64 | H15: 86 | I15: 109 | K15: =IF(AND(ISNUMBER(E15),ISNUMBER(H15)),H15/E15-1,"") -> 0.22857143 | L15: 8.7 | M15: 8.5 | N15: 9 | O15: =IF(COUNT(L15:N15)=3,AVERAGE(L15:N15),"") -> 8.7333333
A16: 追蹤中 | B16: 台股 | C16: 3529 | D16: =IFERROR(INDEX('公司檔案'!$B:$B,MATCH(C16,'公司檔案'!$A:$A,0)),"請先到公司檔案新增") -> 力旺 | E16: 2300 | F16: 2150 | G16: 2100 | H16: 3000 | I16: 3700 | J16: 4200 | K16: =IF(AND(ISNUMBER(E16),ISNUMBER(H16)),H16/E16-1,"") -> 0.30434783 | L16: 8.6 | O16: =IF(COUNT(L16:N16)=3,AVERAGE(L16:N16),"")
A17: 追蹤中 | B17: 台股 | C17: 2337 | D17: =IFERROR(INDEX('公司檔案'!$B:$B,MATCH(C17,'公司檔案'!$A:$A,0)),"請先到公司檔案新增") -> 旺宏 | E17: 125 | F17: 118 | G17: 101 | H17: 160 | I17: 190 | J17: 220 | K17: =IF(AND(ISNUMBER(E17),ISNUMBER(H17)),H17/E17-1,"") -> 0.28 | L17: 8.9 | O17: =IF(COUNT(L17:N17)=3,AVERAGE(L17:N17),"")
A18: 追蹤中 | B18: 台股 | C18: 6139 | D18: =IFERROR(INDEX('公司檔案'!$B:$B,MATCH(C18,'公司檔案'!$A:$A,0)),"請先到公司檔案新增") -> 亞翔 | E18: 770 | G18: 750 | H18: 980 | I18: 1100 | K18: =IF(AND(ISNUMBER(E18),ISNUMBER(H18)),H18/E18-1,"") -> 0.27272727 | L18: 8.5 | M18: 9.5 | N18: 8.5 | O18: =IF(COUNT(L18:N18)=3,AVERAGE(L18:N18),"") -> 8.8333333 | P18: 730-750建議買滿
A19: 追蹤中 | B19: 台股 | C19: 3081 | D19: =IFERROR(INDEX('公司檔案'!$B:$B,MATCH(C19,'公司檔案'!$A:$A,0)),"請先到公司檔案新增") -> 聯亞 | E19: 2600 | F19: 2500 | G19: 2200 | H19: 2400 | I19: 3800 | J19: 4000 | K19: =IF(AND(ISNUMBER(E19),ISNUMBER(H19)),H19/E19-1,"") -> -0.076923077 | L19: 9.1 | O19: =IF(COUNT(L19:N19)=3,AVERAGE(L19:N19),"")
A20: 追蹤中 | B20: 台股 | C20: 3376 | D20: =IFERROR(INDEX('公司檔案'!$B:$B,MATCH(C20,'公司檔案'!$A:$A,0)),"請先到公司檔案新增") -> 新日興 | E20: 210 | G20: 201 | H20: 250 | I20: 280 | J20: 350 | K20: =IF(AND(ISNUMBER(E20),ISNUMBER(H20)),H20/E20-1,"") -> 0.19047619 | L20: 8.8 | O20: =IF(COUNT(L20:N20)=3,AVERAGE(L20:N20),"")
A21: 追蹤中 | B21: 美股 | C21: CRDO | D21: =IFERROR(INDEX('公司檔案'!$B:$B,MATCH(C21,'公司檔案'!$A:$A,0)),"請先到公司檔案新增") -> Credo | E21: 225 | F21: 212 | G21: 200 | H21: 280 | I21: 360 | J21: 410 | K21: =IF(AND(ISNUMBER(E21),ISNUMBER(H21)),H21/E21-1,"") -> 0.24444444 | L21: 8.9 | O21: =IF(COUNT(L21:N21)=3,AVERAGE(L21:N21),"")
A22: 追蹤中 | B22: 台股 | C22: 2337 | D22: =IFERROR(INDEX('公司檔案'!$B:$B,MATCH(C22,'公司檔案'!$A:$A,0)),"請先到公司檔案新增") -> 旺宏 | E22: 130 | G22: 120 | H22: 180 | I22: 225 | K22: =IF(AND(ISNUMBER(E22),ISNUMBER(H22)),H22/E22-1,"") -> 0.38461538 | L22: 8.4 | O22: =IF(COUNT(L22:N22)=3,AVERAGE(L22:N22),"")
A23: 追蹤中 | B23: 台股 | C23: 7610 | D23: =IFERROR(INDEX('公司檔案'!$B:$B,MATCH(C23,'公司檔案'!$A:$A,0)),"請先到公司檔案新增") -> 聯友金屬-創 | E23: 1900 | F23: 1660 | G23: 1500 | H23: 2400 | I23: 3100 | K23: =IF(AND(ISNUMBER(E23),ISNUMBER(H23)),H23/E23-1,"") -> 0.26315789 | L23: 9 | O23: =IF(COUNT(L23:N23)=3,AVERAGE(L23:N23),"")
A24: 追蹤中 | B24: 台股 | C24: 6725 | D24: =IFERROR(INDEX('公司檔案'!$B:$B,MATCH(C24,'公司檔案'!$A:$A,0)),"請先到公司檔案新增") -> 矽科宏晟 | E24: 300 | G24: 285 | H24: 420 | I24: 652 | K24: =IF(AND(ISNUMBER(E24),ISNUMBER(H24)),H24/E24-1,"") -> 0.4 | L24: 8.5 | M24: 9 | N24: 9 | O24: =IF(COUNT(L24:N24)=3,AVERAGE(L24:N24),"") -> 8.8333333
A25: 追蹤中 | B25: 台股 | C25: 2441 | D25: =IFERROR(INDEX('公司檔案'!$B:$B,MATCH(C25,'公司檔案'!$A:$A,0)),"請先到公司檔案新增") -> 超豐 | E25: 120 | G25: 111 | H25: 155 | I25: 173 | K25: =IF(AND(ISNUMBER(E25),ISNUMBER(H25)),H25/E25-1,"") -> 0.29166667 | L25: 8.6 | M25: 5 | N25: 8 | O25: =IF(COUNT(L25:N25)=3,AVERAGE(L25:N25),"") -> 7.2
A26: 追蹤中 | B26: 台股 | C26: 4966 | D26: =IFERROR(INDEX('公司檔案'!$B:$B,MATCH(C26,'公司檔案'!$A:$A,0)),"請先到公司檔案新增") -> 譜瑞-KY | G26: 560 | H26: 702 | I26: 910 | K26: =IF(AND(ISNUMBER(E26),ISNUMBER(H26)),H26/E26-1,"") | L26: 7.5 | M26: 9.5 | N26: 7 | O26: =IF(COUNT(L26:N26)=3,AVERAGE(L26:N26),"") -> 8
A27: 追蹤中 | B27: 台股 | C27: 4971 | D27: =IFERROR(INDEX('公司檔案'!$B:$B,MATCH(C27,'公司檔案'!$A:$A,0)),"請先到公司檔案新增") -> IET-KY | E27: 420 | G27: 390 | H27: 620 | I27: 810 | K27: =IF(AND(ISNUMBER(E27),ISNUMBER(H27)),H27/E27-1,"") -> 0.47619048 | L27: 8.4 | O27: =IF(COUNT(L27:N27)=3,AVERAGE(L27:N27),"") | P27: 過440買
A28: 追蹤中 | B28: 台股 | C28: 5347 | D28: =IFERROR(INDEX('公司檔案'!$B:$B,MATCH(C28,'公司檔案'!$A:$A,0)),"請先到公司檔案新增") -> 世界 | E28: 195 | G28: 190 | H28: 260 | I28: 350 | J28: 450 | K28: =IF(AND(ISNUMBER(E28),ISNUMBER(H28)),H28/E28-1,"") -> 0.33333333 | L28: 9.1 | M28: 6 | N28: 9 | O28: =IF(COUNT(L28:N28)=3,AVERAGE(L28:N28),"") -> 8.0333333 | P28: 做最後一次加碼
A29: 追蹤中 | B29: 台股 | C29: 6805 | D29: =IFERROR(INDEX('公司檔案'!$B:$B,MATCH(C29,'公司檔案'!$A:$A,0)),"請先到公司檔案新增") -> 富世達 | E29: 1635 | G29: 1470 | H29: 2100 | I29: 2400 | K29: =IF(AND(ISNUMBER(E29),ISNUMBER(H29)),H29/E29-1,"") -> 0.28440367 | L29: 8 | O29: =IF(COUNT(L29:N29)=3,AVERAGE(L29:N29),"") | P29: 收過1690買比較安全
A30: 追蹤中 | B30: 台股 | C30: 8299 | D30: =IFERROR(INDEX('公司檔案'!$B:$B,MATCH(C30,'公司檔案'!$A:$A,0)),"請先到公司檔案新增") -> 群聯 | E30: 2500 | F30: 2200 | G30: 2100 | H30: 3400 | I30: 3900 | J30: 4400 | K30: =IF(AND(ISNUMBER(E30),ISNUMBER(H30)),H30/E30-1,"") -> 0.36 | L30: 9 | O30: =IF(COUNT(L30:N30)=3,AVERAGE(L30:N30),"")
A31: 追蹤中 | B31: 台股 | C31: 4989 | D31: =IFERROR(INDEX('公司檔案'!$B:$B,MATCH(C31,'公司檔案'!$A:$A,0)),"請先到公司檔案新增") -> 榮科 | E31: 88 | G31: 77 | H31: 130 | I31: 154 | J31: 180 | K31: =IF(AND(ISNUMBER(E31),ISNUMBER(H31)),H31/E31-1,"") -> 0.47727273 | L31: 8.8 | O31: =IF(COUNT(L31:N31)=3,AVERAGE(L31:N31),"")
A32: 追蹤中 | B32: 台股 | C32: 2329 | D32: =IFERROR(INDEX('公司檔案'!$B:$B,MATCH(C32,'公司檔案'!$A:$A,0)),"請先到公司檔案新增") -> 華泰 | E32: 62 | F32: 58 | G32: 54 | H32: 88 | I32: 120 | J32: 150 | K32: =IF(AND(ISNUMBER(E32),ISNUMBER(H32)),H32/E32-1,"") -> 0.41935484 | L32: 9.3 | O32: =IF(COUNT(L32:N32)=3,AVERAGE(L32:N32),"") | P32: 站回56或<54
A33: 追蹤中 | B33: 台股 | C33: 3026 | D33: =IFERROR(INDEX('公司檔案'!$B:$B,MATCH(C33,'公司檔案'!$A:$A,0)),"請先到公司檔案新增") -> 禾伸堂 | E33: 900 | G33: 800 | H33: 1150 | I33: 1350 | J33: 1500 | K33: =IF(AND(ISNUMBER(E33),ISNUMBER(H33)),H33/E33-1,"") -> 0.27777778 | L33: 9.3 | O33: =IF(COUNT(L33:N33)=3,AVERAGE(L33:N33),"")
A34: 追蹤中 | B34: 台股 | C34: 6147 | D34: =IFERROR(INDEX('公司檔案'!$B:$B,MATCH(C34,'公司檔案'!$A:$A,0)),"請先到公司檔案新增") -> 頎邦 | E34: 215 | G34: 190 | H34: 300 | I34: 345 | K34: =IF(AND(ISNUMBER(E34),ISNUMBER(H34)),H34/E34-1,"") -> 0.39534884 | L34: 8.5 | O34: =IF(COUNT(L34:N34)=3,AVERAGE(L34:N34),"") | P34: 不追高
A35: 追蹤中 | B35: 台股 | C35: 6173 | D35: =IFERROR(INDEX('公司檔案'!$B:$B,MATCH(C35,'公司檔案'!$A:$A,0)),"請先到公司檔案新增") -> 信昌電 | E35: 233 | G35: 200 | H35: 280 | I35: 360 | K35: =IF(AND(ISNUMBER(E35),ISNUMBER(H35)),H35/E35-1,"") -> 0.20171674 | L35: 9.2 | M35: 6 | N35: 7 | O35: =IF(COUNT(L35:N35)=3,AVERAGE(L35:N35),"") -> 7.4
A36: 追蹤中 | B36: 台股 | C36: 6770 | D36: =IFERROR(INDEX('公司檔案'!$B:$B,MATCH(C36,'公司檔案'!$A:$A,0)),"請先到公司檔案新增") -> 力積電 | G36: 78 | H36: 105 | I36: 130 | J36: 170 | K36: =IF(AND(ISNUMBER(E36),ISNUMBER(H36)),H36/E36-1,"") | L36: 8.9 | O36: =IF(COUNT(L36:N36)=3,AVERAGE(L36:N36),"")
A37: 追蹤中 | B37: 台股 | C37: 2329 | D37: =IFERROR(INDEX('公司檔案'!$B:$B,MATCH(C37,'公司檔案'!$A:$A,0)),"請先到公司檔案新增") -> 華泰 | E37: 60 | G37: 57 | H37: 75 | I37: 100 | J37: 120 | K37: =IF(AND(ISNUMBER(E37),ISNUMBER(H37)),H37/E37-1,"") -> 0.25 | L37: 9.2 | O37: =IF(COUNT(L37:N37)=3,AVERAGE(L37:N37),"")
A38: 追蹤中 | B38: 台股 | C38: 3026 | D38: =IFERROR(INDEX('公司檔案'!$B:$B,MATCH(C38,'公司檔案'!$A:$A,0)),"請先到公司檔案新增") -> 禾伸堂 | E38: 590 | F38: 570 | G38: 520 | H38: 720 | I38: 860 | J38: 990 | K38: =IF(AND(ISNUMBER(E38),ISNUMBER(H38)),H38/E38-1,"") -> 0.22033898 | L38: 9.3 | O38: =IF(COUNT(L38:N38)=3,AVERAGE(L38:N38),"")
A39: 追蹤中 | B39: 台股 | C39: 6488 | D39: =IFERROR(INDEX('公司檔案'!$B:$B,MATCH(C39,'公司檔案'!$A:$A,0)),"請先到公司檔案新增") -> 環球晶 | E39: 800 | G39: 750 | H39: 980 | I39: 1200 | J39: 1390 | K39: =IF(AND(ISNUMBER(E39),ISNUMBER(H39)),H39/E39-1,"") -> 0.225 | L39: 9.3 | O39: =IF(COUNT(L39:N39)=3,AVERAGE(L39:N39),"")
A40: 追蹤中 | B40: 台股 | C40: 7734 | D40: =IFERROR(INDEX('公司檔案'!$B:$B,MATCH(C40,'公司檔案'!$A:$A,0)),"請先到公司檔案新增") -> 印能 | G40: 3300 | H40: 4600 | I40: 5400 | J40: 6100 | K40: =IF(AND(ISNUMBER(E40),ISNUMBER(H40)),H40/E40-1,"") | L40: 9.3 | O40: =IF(COUNT(L40:N40)=3,AVERAGE(L40:N40),"")
...

Sheet 公司檔案
A1: 代號 | B1: 名稱 | C1: 市場 | D1: 產業 | E1: 股本(億元) | F1: 一句話定位 | G1: 主要業務 | H1: AI 題材 | I1: AI 題材說明 | J1: 資料日期
A2: 6147 | B2: 頎邦 | C2: 台股 | D2: 半導體封測 | E2: 74.46 | F2: 驅動 IC 金凸塊與 COF 封測龍頭 | G2: 專做面板驅動 IC 的金凸塊（Gold Bumping）、晶圓測試，以及 COF、COG 等捲帶與玻璃覆晶封裝，是 LCD／OLED 驅動 IC 後段製程的主要供應商。 | H2: 矽光子、CPO、LDDI | I2: 市場關注點是凸塊技術延伸到矽光子／共同封裝光學（CPO）元件的封裝，以及大尺寸驅動 IC（LDDI）需求回溫。 | J2: 46302
A3: 3037 | B3: 欣興 | C3: 台股 | D3: PCB／IC 載板 | E3: 164.13 | F3: ABF 載板與高階 PCB 龍頭 | G3: 全球主要的 IC 載板（ABF、BT）與 HDI、軟硬板廠，客戶涵蓋 CPU、GPU 與網通晶片大廠。 | H3: ABF 載板、AI GPU、ASIC | I3: AI 加速器晶片面積大、層數高，帶動高階 ABF 載板用量與單價，是 AI 伺服器上游的關鍵材料供應鏈。 | J3: 46302
A4: 2344 | B4: 華邦電 | C4: 台股 | D4: 記憶體 | E4: 450 | F4: 利基型 DRAM 與 NOR／NAND Flash | G4: 自有晶圓廠的記憶體公司，產品包括利基型 DRAM、Code Storage Flash（NOR、SLC NAND），應用在消費性、車用、工控與網通。 | H4: 記憶體漲價、CUBE、邊緣 AI | I4: 受惠於大廠把產能轉向 HBM 造成的利基型 DRAM 供給吃緊；自家 CUBE 客製化高頻寬記憶體鎖定邊緣 AI 裝置。 | J4: 46302
A5: 6531 | B5: 愛普 | C5: 台股 | D5: IC 設計／記憶體 IP | E5: 8.16 | F5: PSRAM 與矽電容，打進先進封裝 | G5: 以 IoT 用的低功耗 PSRAM 起家，另發展 AI 用的客製化記憶體（VHM）與矽電容（S-SiCap）。 | H5: 矽電容、CoWoS、HBM 周邊 | I5: 矽電容可整合進 CoWoS 等先進封裝做為電源去耦，是 AI 晶片供電穩定的關鍵零件之一。 | J5: 46302
A6: 3653 | B6: 健策 | C6: 台股 | D6: 散熱 | E6: 14.72 | F6: 均熱片與液冷散熱模組 | G6: 精密沖壓與散熱零件廠，主力為 CPU／GPU 均熱片（Lid）、IGBT 散熱基板，並延伸到液冷相關元件。 | H6: 均熱片、液冷、AI 伺服器 | I6: AI GPU 與 ASIC 功耗大增，高階均熱片和液冷冷板、分歧管需求上升，健策是主要供應商。 | J6: 46302
A7: 3665 | B7: 貿聯-KY | C7: 台股 | D7: 線材／連接器 | E7: 19.96 | F7: 高速線束與伺服器連接線組 | G7: 線束與連接線組廠，產品涵蓋電腦週邊、車用、醫療、工業與資料中心用線材。 | H7: 高速傳輸線、AI 伺服器、電源線束 | I7: AI 伺服器機櫃內部大量使用高速銅纜與電源線束，貿聯是一線 GPU 伺服器供應鏈。 | J7: 46302
A8: 3595 | B8: 山太士 | C8: 台股 | D8: 製程材料 | F8: 面板與先進封裝製程保護膜 | G8: 製程用保護膜與耗材供應商，從面板製程材料延伸到半導體先進封裝製程。 | H8: 先進封裝材料、CoWoS | I8: 市場關注其先進封裝製程材料打入晶圓代工供應鏈，隨 CoWoS 擴產成長。
A9: 3081 | B9: 聯亞 | C9: 台股 | D9: 光通訊磊晶 | E9: 9.25 | F9: InP 雷射與檢光磊晶片 | G9: 研發生產雷射磊晶片與檢光器磊晶片（InP 為主），是光通訊雷射晶片的上游。 | H9: 矽光子、CW 雷射、800G／1.6T | I9: 矽光子與 CPO 需要大量高功率 CW 雷射光源，資料中心光模組升級到 800G、1.6T 帶動磊晶需求。 | J9: 46302
A10: 2327 | B10: 國巨 | C10: 台股 | D10: 被動元件 | E10: 51.47 | F10: 全球被動元件龍頭 | G10: 被動元件大廠，產品包括晶片電阻、MLCC、鉭質電容、電感、天線與感測器，並透過併購擴大車用與工業比重。 | H10: AI 伺服器 MLCC、鉭電容、電源管理 | I10: AI 伺服器單機用的高階 MLCC 與鉭電容數量是一般伺服器的數倍，高容值、高耐壓產品吃緊。 | J10: 46302
A11: 3533 | B11: 嘉澤 | C11: 台股 | D11: 連接器 | E11: 11.25 | F11: CPU／GPU Socket 連接器 | G11: 專做 CPU Socket、高速連接器、記憶體插槽等連接器產品，主要客戶為 CPU 與伺服器大廠。 | H11: GPU Socket、高速連接器、AI 伺服器 | I11: AI 伺服器 GPU 模組與 CPU 平台世代更替，Socket 與高速背板連接器規格、單價同步提升。 | J11: 46302
A12: 6907 | B12: 雅特力-KY | C12: 台股 | D12: IC 設計 | E12: 6.25 | F12: ARM 架構 MCU 設計 | G12: 微控制器（MCU）IC 設計公司，產品以 ARM Cortex-M 架構為主，用於工控、消費性電子與馬達控制。 | H12: MCU、邊緣 AI | I12: AI 直接題材較少，主要看 MCU 庫存回補與邊緣運算裝置需求。 | J12: 46302
A13: 7769 | B13: 鴻勁 | C13: 台股 | D13: 半導體設備 | E13: 17.99 | F13: IC 測試分選機與溫控方案 | G13: IC 測試分選機（Handler）及整合性解決方案，具備主動溫控技術。 | H13: AI 晶片測試、主動溫控、測試時間拉長 | I13: AI 晶片功耗高、測試時間長，需要具主動溫控的分選機，測試設備數量與單價同步提升。 | J13: 46302
A14: 6190 | B14: 萬泰科 | C14: 台股 | D14: 線材 | E14: 18.65 | F14: 網路線、電源線與電子線材 | G14: 生產區域網路線、電子線、汽機車用線與電源線。 | H14: 資料中心線材 | I14: 題材在資料中心網路與電源線材需求，屬 AI 伺服器周邊。 | J14: 46302
A15: 3529 | B15: 力旺 | C15: 台股 | D15: 矽智財 IP | E15: 7.47 | F15: 嵌入式非揮發記憶體 IP | G15: 嵌入式非揮發記憶體（NeoBit、NeoFuse OTP 等）IP 授權與技術服務，收入來自授權金與權利金。 | H15: 先進製程 IP、PUF 安全、權利金 | I15: AI 晶片多採先進製程，力旺 IP 隨晶圓投片收取權利金；PUF 硬體安全方案受關注。 | J15: 46302
A16: 2337 | B16: 旺宏 | C16: 台股 | D16: 記憶體 | E16: 198.19 | F16: NOR Flash 與 ROM 大廠 | G16: 非揮發性記憶體 IDM，主力為 NOR Flash、NAND Flash 與 ROM，應用於消費性、車用、工控。 | H16: 記憶體漲價、NOR Flash、AI 伺服器 | I16: 記憶體報價循環向上，AI 伺服器與 AI PC 對 NOR Flash 容量需求提高。 | J16: 46302
A17: 6139 | B17: 亞翔 | C17: 台股 | D17: 廠務工程 | E17: 23.56 | F17: 無塵室機電整合工程 | G17: 高科技廠房無塵室、機電與製程管線的設計建造，客戶以晶圓廠、面板廠與生技廠為主。 | H17: 晶圓廠擴廠、先進封裝廠 | I17: AI 帶動晶圓代工與先進封裝擴產，國內外新廠的無塵室工程是主要訂單來源。 | J17: 46302
A18: 3376 | B18: 新日興 | C18: 台股 | D18: 機構件 | E18: 19.58 | F18: 筆電與手機樞紐（轉軸） | G18: 筆電、手機、顯示器等 3C 產品的樞紐研發製造，以及精密金屬沖壓件與彈簧。 | H18: AI PC 換機 | I18: 題材主要在 AI PC 換機潮帶動的筆電出貨與轉軸升級。 | J18: 46302
A19: CRDO | B19: Credo | C19: 美股 | D19: 美股・半導體 | F19: AEC 主動式電纜與 SerDes | G19: 高速連接方案公司，產品包括主動式電纜（AEC）、光模組 DSP 與 SerDes IP。 | H19: AEC、資料中心互連 | I19: AI 機櫃內短距互連大量改用 AEC，Credo 是主要供應商。
A20: 7610 | B20: 聯友金屬-創 | C20: 台股 | D20: 金屬材料 | E20: 5.83 | F20: 鎢、鈷化學品（創新板） | G20: 生產鎢酸鈉與硫酸鈷等金屬化學品，上市於創新板。 | H20: 戰略金屬、鎢價 | I20: AI 題材間接，主要看鎢、鈷等戰略金屬的價格走勢。 | J20: 46302
A21: 6725 | B21: 矽科宏晟 | C21: 台股 | D21: 廠務系統 | E21: 3.71 | F21: 高科技廠製程廠務系統整合 | G21: 高科技產業的製程廠務系統整合工程、製程供應系統設備，以及後續維護保養。 | H21: 晶圓廠擴廠、廠務工程 | I21: 跟著晶圓廠與先進封裝擴產走，接單能見度看大客戶資本支出。 | J21: 46302
A22: 2441 | B22: 超豐 | C22: 台股 | D22: 半導體封測 | E22: 56.88 | F22: 傳統 IC 封裝測試 | G22: 各種積體電路的封裝與測試，以導線架等傳統封裝為主，屬力成集團。 | H22: 封測產能 | I22: AI 直接題材有限，主要看消費性與車用晶片的封測需求。 | J22: 46302
A23: 4966 | B23: 譜瑞-KY | C23: 台股 | D23: IC 設計 | E23: 7.9 | F23: 高速傳輸介面與顯示晶片 | G23: 高速訊號傳輸介面（DisplayPort、USB、PCIe Retimer 等）與顯示、觸控晶片設計。 | H23: PCIe Retimer、高速介面、AI 伺服器 | I23: AI 伺服器內部高速傳輸需要 Retimer 晶片，是譜瑞跨入資料中心的方向。 | J23: 46302
A24: 4971 | B24: IET-KY | C24: 台股 | D24: 化合物半導體 | E24: 4.72 | F24: GaAs／InP 磊晶片 | G24: 化合物半導體磊晶片廠，產品包括 GaAs pHEMT、InP HBT 與 GaSb 紅外線磊晶片。 | H24: InP、光通訊、矽光子 | I24: InP 磊晶用於高速光通訊元件，受惠資料中心光模組升級。 | J24: 46302
A25: 5347 | B25: 世界 | C25: 台股 | D25: 晶圓代工 | E25: 187.83 | F25: 特殊製程晶圓代工 | G25: 8 吋與 12 吋特殊製程晶圓代工，主力為電源管理 IC、顯示驅動 IC 與分離式元件，並與恩智浦合資在新加坡建 12 吋廠（VSMC）。 | H25: VSMC、電源管理 IC、AI 伺服器供電 | I25: AI 伺服器電源架構升級帶動電源管理 IC 投片；VSMC 12 吋廠是中長期成長主軸。 | J25: 46302
A26: 6805 | B26: 富世達 | C26: 台股 | D26: 機構件／散熱 | E26: 6.86 | F26: 樞紐與液冷快接頭 | G26: 3C 產品樞紐（含摺疊手機轉軸）廠，並跨入 AI 伺服器液冷系統的快接頭。 | H26: 液冷快接頭、UQD、摺疊機 | I26: AI 伺服器導入液冷，快接頭用量大增，是富世達主要的成長題材。 | J26: 46302
A27: 8299 | B27: 群聯 | C27: 台股 | D27: IC 設計／儲存 | E27: 22.11 | F27: NAND 控制晶片與儲存方案 | G27: NAND Flash 控制晶片與儲存解決方案設計，產品涵蓋消費性、工控與企業級 SSD。 | H27: 企業級 SSD、aiDAPTIV+、NAND 漲價 | I27: AI 推論帶動企業級 SSD 需求，自家 aiDAPTIV+ 用 SSD 擴充 GPU 記憶體做地端 AI 訓練。 | J27: 46302
A28: 4989 | B28: 榮科 | C28: 台股 | D28: 材料 | E28: 17.28 | F28: 電解銅箔 | G28: 電解銅箔的製造與銷售，應用於印刷電路板。 | H28: 高頻高速銅箔、AI 伺服器 PCB | I28: AI 伺服器板材升級需要低粗糙度的高階銅箔，帶動產品組合轉佳。 | J28: 46302
A29: 2329 | B29: 華泰 | C29: 台股 | D29: 半導體封測 | E29: 65.89 | F29: 記憶體封測與 EMS | G29: 積體電路封裝測試與電子製造服務，記憶體封測是主力之一。 | H29: 記憶體封測、NAND | I29: 跟著記憶體景氣循環，NAND 與 DRAM 拉貨帶動封測稼動率。 | J29: 46302
A30: 3026 | B30: 禾伸堂 | C30: 台股 | D30: 被動元件 | E30: 16.59 | F30: MLCC 與被動元件 | G30: 被動元件（MLCC 等）、系統模組與主動元件的製造與代理。 | H30: 高容 MLCC、AI 伺服器 | I30: 受惠 AI 伺服器與電源相關高階 MLCC 需求。 | J30: 46302
A31: 6173 | B31: 信昌電 | C31: 台股 | D31: 被動元件 | E31: 17.12 | F31: 晶片電容、電阻與介電瓷粉 | G31: 晶片電容、晶片電阻、介電瓷粉與電感，瓷粉是 MLCC 的關鍵原料。 | H31: MLCC 材料、被動元件漲價 | I31: 被動元件景氣回升時，上游瓷粉與高階 MLCC 同步受惠。 | J31: 46302
... A35: 3661 | B35: 世芯-KY | C35: 台股 | D35: IC 設計服務 | E35: 8.63 | F35: 雲端 AI ASIC 設計服務 | G35: 專業 ASIC 與 SoC 設計及委託生產服務，以先進製程與大型晶片見長。 | H35: AI ASIC、雲端客戶、3nm／2nm | I35: 美系雲端大廠自研 AI 加速器的設計服務夥伴，營運高度連動 AI ASIC 量產節奏。 | J35: 46302
A36: 6723 | B36: 瑞薩 | C36: 日股 | D36: 日股・半導體 | F36: 車用與工控 MCU 大廠 | G36: 日本半導體公司，主力為 MCU、類比與電源晶片，車用比重高。 | H36: MCU、電源管理 | I36: 主要看車用與工控景氣回溫，AI 相關在資料中心電源方案。
A37: 7751 | B37: 竑騰 | C37: 台股 | D37: 半導體設備 | E37: 2.69 | F37: 先進封裝自動化設備 | G37: 半導體自動化生產與光學檢測設備，以及相關治具、零件與維修。 | H37: CoWoS、先進封裝設備 | I37: 先進封裝擴產帶動自動化貼合與檢測設備需求。 | J37: 46302
A38: 2408 | B38: 南亞科 | C38: 台股 | D38: 記憶體 | E38: 345.02 | F38: 標準型 DRAM 製造 | G38: 台灣主要的 DRAM 製造商，產品以 DDR4、DDR5 與低功耗 DRAM 為主。 | H38: DRAM 漲價、DDR5、HBM 排擠效應 | I38: 國際大廠產能轉向 HBM，標準型 DRAM 供給吃緊、報價上漲。 | J38: 46302
A39: ALAB | B39: Astera Labs | C39: 美股 | D39: 美股・半導體 | F39: PCIe／CXL Retimer 與交換晶片 | G39: 資料中心連接晶片公司，產品有 PCIe／CXL Retimer、Scorpio 交換晶片與智慧線纜模組。 | H39: PCIe Retimer、Scorpio、AI 機櫃 | I39: AI 伺服器 GPU 與 CPU 之間的高速連接，ALAB 是關鍵晶片供應商。
A40: NBIS | B40: Nebius | C40: 美股 | D40: 美股・AI 雲端 | F40: GPU 雲端服務 | G40: AI 基礎設施公司，提供 GPU 雲端運算與 AI 開發平台。 | H40: GPU 雲、Neocloud | I40: 新型態 AI 雲端業者（Neocloud），營收跟著 GPU 叢集擴建與大客戶合約成長。
A41: 285A | B41: Kioxia | C41: 日股 | D41: 日股・記憶體 | F41: NAND Flash 大廠 | G41: 日本 NAND Flash 製造商，前身為東芝記憶體。 | H41: 企業級 SSD、NAND 漲價 | I41: AI 推論與資料中心帶動企業級 SSD 需求，NAND 報價回升。
A42: 3110 | B42: 日東紡 | C42: 日股 | D42: 日股・材料 | F42: 高階玻纖布（T-glass） | G42: 日本玻璃纖維大廠，生產 IC 載板與 PCB 用的低膨脹、低介電玻纖布。 | H42: T-glass、ABF 載板材料 | I42: AI 晶片載板需要低膨脹 T-glass 玻纖布，日東紡是主要供應商且供給吃緊。
A43: AAOI | B43: Applied Opto | C43: 美股 | D43: 美股・光通訊 | F43: 光收發模組 | G43: 光通訊元件與收發模組製造商，客戶包括資料中心與有線電視業者。 | H43: 800G 光模組、資料中心 | I43: 資料中心光模組升級到 800G 與 1.6T 的受惠股。
...

Sheet 檢討
A1: 日期 | B1: 問題 | C1: # | D1: 改進原則
A2: 46204 | B2: 死抱股票回檔太大 | C2: 1 | D2: 照評分配置部位大小
A3: 46204 | B3: 死抱股票回檔太大 | C3: 2 | D3: fwd PE 在歷史上數字相對高 就是要注意風險
A4: 46204 | B4: 死抱股票回檔太大 | C4: 3 | D4: 先訂出最有可能的目標價 然後分區加碼點位 目的是為為了避免在同樣的價格附近一直加碼
A5: 46204 | B5: 死抱股票回檔太大 | C5: 4 | D5: 總部位獲利到達一定程度後 降槓桿 看是保留現金或是換現股

Sheet 說明
A1: 分頁介紹
A2: 儀表板 | B2: 在黃色格子的下拉選單挑一檔，下方自動帶出公司小檔案、價位、評分與備註。這頁全部是公式，不用手打
A3: 標的清單 | B3: 你的買點、目標價、評分、備註都在這裡維護。名稱會自動從「公司檔案」帶入
A4: 公司檔案 | B4: 每檔公司一列：產業、股本、一句話定位、主要業務、AI 題材，想改就直接改
A5: 檢討 | B5: 交易檢討紀錄
A7: 新增一檔股票（兩步）
A8: 步驟 1 | B8: 到「公司檔案」最後一列的下一列填代號、名稱、市場等資料（表格會自動延伸）
A9: 步驟 2 | B9: 到「標的清單」最後一列的下一列填代號和價位；名稱、TP1 漲幅、平均分會自動算好
A10: 完成 | B10: 回到「儀表板」，下拉選單裡就會出現這檔
A12: 欄位規則
A13: 價位欄（買點、TP） | B13: 只放數字。「附近、<、區間、147X」這類說明寫在「備註」
A14: 評分欄 | B14: 0–10 的數字，三項都填才會算平均分
A15: 股本 | B15: 單位億元，例如 9.25；儀表板會自動換算成股數（面額 10 元）
A16: 粗體欄位 | B16: 公式（名稱、TP1 漲幅、平均分），不要手打
A18: 顏色代表什麼
A19: 黃底分類 | B19: 今日即時標的
A20: 紅底代號 | B20: 代號重複出現 → 可能是舊價位沒刪，請確認要保留哪一列
A21: 淺黃底價位 | B21: 原本是文字、已轉成數字；滑鼠移上去可看原本寫法，確認後可清掉黃底
A23: 常用連結
A24: Market dashboard | B24: https://adamsnet.github.io/market-dashboard/union10f.html
